<mujoco model="VMP_DESCRIPTION">
    <compiler angle="radian" autolimits="true"/>
    <!-- <size njmax="500" nconmax="100" /> -->
    <asset>
        <mesh name="pelvis" file="pelvis.STL" />
        <mesh name="left_hip_yaw_link" file="left_hip_yaw_link.STL" />
        <mesh name="left_hip_roll_link" file="left_hip_roll_link.STL" />
        <mesh name="left_hip_pitch_link" file="left_hip_pitch_link.STL" />
        <mesh name="left_knee_link" file="left_knee_link.STL" />
        <mesh name="left_ankle_link" file="left_ankle_link.STL" />
        <mesh name="right_hip_yaw_link" file="right_hip_yaw_link.STL" />
        <mesh name="right_hip_roll_link" file="right_hip_roll_link.STL" />
        <mesh name="right_hip_pitch_link" file="right_hip_pitch_link.STL" />
        <mesh name="right_knee_link" file="right_knee_link.STL" />
        <mesh name="right_ankle_link" file="right_ankle_link.STL" />
        <mesh name="torso_link" file="torso_link.STL" />
        <mesh name="left_shoulder_pitch_link" file="left_shoulder_pitch_link.STL" />
        <mesh name="left_shoulder_roll_link" file="left_shoulder_roll_link.STL" />
        <mesh name="left_shoulder_yaw_link" file="left_shoulder_yaw_link.STL" />
        <mesh name="right_shoulder_yaw_link" file="right_shoulder_yaw_link.STL" />
        <mesh name="left_elbow_link" file="left_elbow_link.STL" />
        <mesh name="right_shoulder_pitch_link" file="right_shoulder_pitch_link.STL" />
        <mesh name="right_shoulder_roll_link" file="right_shoulder_roll_link.STL" />
        <mesh name="right_elbow_link" file="right_elbow_link.STL" />
        <mesh name="head_yaw_Link" file="head_yaw_Link.STL" />
        <mesh name="head_pitch_Link" file="head_pitch_Link.STL" />
        <mesh name="imu_Link" file="imu_Link.STL" />
    </asset>
    <worldbody>
        <body name="pelvis" pos="0 0 0.58" childclass="body">
            <inertial pos="-0.00256788 -0.000887834 0.0146801" quat="0.455001 0.542074 -0.454039 0.541274" mass="1.8201" diaginertia="0.00718431 0.00466329 0.00342074" />
            <joint name="floating_base_joint" type="free" />
            <geom type="mesh" contype="0" conaffinity="0" group="1" rgba="1 1 1 1" mesh="pelvis" />
            <geom type="mesh" rgba="1 1 1 1" mesh="pelvis" />
            <body name="left_hip_yaw_link" pos="-0.05016 0.069802 -0.091014">
                <inertial pos="-0.015992 -0.0100206 0.0347848" quat="-0.147175 0.411439 -0.124858 0.890768" mass="0.280646" diaginertia="0.000485582 0.000409941 0.000313819" />
                <!-- <joint name="left_hip_yaw_joint" pos="0 0 0" axis="0.0593912 -0.336821 0.939694" limited="true" range="-0.43 0.43" /> -->
                <joint name="left_hip_yaw_joint_x" pos="0 0 0" axis="0.0593912 0 0" range="-0.43 0.43" />
                <joint name="left_hip_yaw_joint_y" pos="0 0 0" axis="0 -0.336821 0" range="-0.43 0.43" />
                <joint name="left_hip_yaw_joint_z" pos="0 0 0" axis="0 0 0.939694" range="-0.43 0.43" />
                <geom type="mesh" contype="0" conaffinity="0" group="1" rgba="0.196078 1 0.407843 1" mesh="left_hip_yaw_link" />
                <geom type="mesh" rgba="0.196078 1 0.407843 1" mesh="left_hip_yaw_link" />
                <!-- <body name="left_hip_roll_link" pos="-0.030131 -0.00028582 0.0018019">
                    <inertial pos="0.0291452 0.0234324 0.00131548" quat="0.276811 0.327404 0.642524 0.635095" mass="0.231534" diaginertia="0.00034792 0.000303301 0.000158138" />
                    <joint name="left_hip_roll_joint" pos="0 0 0" axis="-0.984808 -0.17365 0" limited="true" range="-0.43 0.43" />
                    <geom type="mesh" contype="0" conaffinity="0" group="1" rgba="1 1 1 1" mesh="left_hip_roll_link" />
                    <geom type="mesh" rgba="1 1 1 1" mesh="left_hip_roll_link" />
                    <body name="left_hip_pitch_link" pos="0.070711 -0.0048448 0.0010654">
                        <inertial pos="-0.000247986 0.0307287 -0.0715485" quat="0.628138 -0.00867798 -0.0152677 0.777904" mass="0.487676" diaginertia="0.00120253 0.00087891 0.000476797" />
                        <joint name="left_hip_pitch_joint" pos="0 0 0" axis="0.17365 -0.984808 0" limited="true" range="-3.14 2.53" />
                        <geom type="mesh" contype="0" conaffinity="0" group="1" rgba="0.101961 0.101961 0.101961 1" mesh="left_hip_pitch_link" />
                        <geom type="mesh" rgba="0.101961 0.101961 0.101961 1" mesh="left_hip_pitch_link" /> -->
                        <body name="left_knee_link" pos="-0.00059469 -0.00010486 -0.14106">
                            <inertial pos="-0.00626002 0.0395185 -0.0898519" quat="0.656569 -0.0154605 0.0479368 0.752582" mass="0.602703" diaginertia="0.00193237 0.00159426 0.00044693" />
                            <joint name="left_knee_joint" pos="0 0 0" axis="0.17365 -0.984808 0" limited="true" range="-0.26 2.05" />
                            <geom type="mesh" contype="0" conaffinity="0" group="1" rgba="1 1 1 1" mesh="left_knee_link" />
                            <geom type="mesh" rgba="1 1 1 1" mesh="left_knee_link" />
                            <body name="left_ankle_link" pos="0.0089064 0.044489 -0.16864">
                                <inertial pos="-0.00895454 -0.0100809 -0.0539967" quat="0.543527 0.357164 0.644292 0.402368" mass="0.408972" diaginertia="0.00127809 0.00109602 0.000309188" />
                                <joint name="left_ankle_joint" pos="0 0 0" axis="-0.17365 0.984808 0" limited="true" range="-0.87 0.52" />
                                <geom type="mesh" contype="0" conaffinity="0" group="1" rgba="1 1 1 1" mesh="left_ankle_link" />
                                <geom type="mesh" rgba="1 1 1 1" mesh="left_ankle_link" />
                            </body>
                        </body>
                    <!-- </body> -->
                <!-- </body> -->
            </body>
            <body name="right_hip_yaw_link" pos="-0.023261 -0.082748 -0.091014">
                <inertial pos="-0.0184537 0.00394734 0.0347846" quat="-0.00974322 0.383504 0.194461 0.902781" mass="0.280636" diaginertia="0.000485599 0.00040994 0.000313841" />
                <!-- <joint name="right_hip_yaw_joint" pos="0 0 0" axis="-0.0593912 0.336821 0.939694" limited="true" range="-0.43 0.43" /> -->
                <joint name="right_hip_yaw_joint_x" pos="0 0 0" axis="-0.0593912 0 0" range="-0.43 0.43" />
                <joint name="right_hip_yaw_joint_y" pos="0 0 0" axis="0 0.336821 0" range="-0.43 0.43" />
                <joint name="right_hip_yaw_joint_z" pos="0 0 0" axis="0 0 0.939694" range="-0.43 0.43" />
                <geom type="mesh" contype="0" conaffinity="0" group="1" rgba="0.196078 1 0.407843 1" mesh="right_hip_yaw_link" />
                <geom type="mesh" rgba="0.196078 1 0.407843 1" mesh="right_hip_yaw_link" />
                <!-- <body name="right_hip_roll_link" pos="-0.028412 -0.010037 0.0018019">
                    <inertial pos="0.0354018 -0.0120509 0.00131553" quat="0.577381 0.575909 0.434004 0.382885" mass="0.231535" diaginertia="0.00034792 0.000303302 0.000158139" />
                    <joint name="right_hip_roll_joint" pos="0 0 0" axis="-0.984808 -0.17365 0" limited="true" range="-0.43 0.43" />
                    <geom type="mesh" contype="0" conaffinity="0" group="1" rgba="1 1 1 1" mesh="right_hip_roll_link" />
                    <geom type="mesh" rgba="1 1 1 1" mesh="right_hip_roll_link" />
                    <body name="right_hip_pitch_link" pos="0.064789 0.028737 0.0010654">
                        <inertial pos="0.010277 -0.02896 -0.071557" quat="0.657021 -0.0135039 -0.0112113 0.753668" mass="0.48764" diaginertia="0.00120242 0.000878794 0.000476775" />
                        <joint name="right_hip_pitch_joint" pos="0 0 0" axis="-0.17365 0.984808 0" limited="true" range="-3.14 2.53" />
                        <geom type="mesh" contype="0" conaffinity="0" group="1" rgba="0.10196 0.10196 0.10196 1" mesh="right_hip_pitch_link" />
                        <geom type="mesh" rgba="0.10196 0.10196 0.10196 1" mesh="right_hip_pitch_link" /> -->
                        <body name="right_knee_link" pos="0.031435 -0.048885 -0.14002">
                            <inertial pos="-0.024396 0.0095047 -0.090894" quat="0.627117 0.0498985 -0.00688965 0.777294" mass="0.60273" diaginertia="0.00193247 0.00159436 0.000446961" />
                            <joint name="right_knee_joint" pos="0 0 0" axis="-0.17365 0.984808 0" limited="true" range="-0.26 2.05" />
                            <geom type="mesh" contype="0" conaffinity="0" group="1" rgba="0.77647 0.75686 0.73725 1" mesh="right_knee_link" />
                            <geom type="mesh" rgba="0.77647 0.75686 0.73725 1" mesh="right_knee_link" />
                            <body name="right_ankle_link" pos="-0.0080996 0.0020294 -0.16979">
                                <inertial pos="-0.012203 0.0144032 -0.0538867" quat="0.301873 0.572482 0.463605 0.605151" mass="0.40893" diaginertia="0.00127798 0.00109592 0.00030918" />
                                <joint name="right_ankle_joint" pos="0 0 0" axis="-0.17365 0.984808 0" limited="true" range="-0.87 0.52" />
                                <geom type="mesh" contype="0" conaffinity="0" group="1" rgba="1 1 1 1" mesh="right_ankle_link" />
                                <geom type="mesh" rgba="1 1 1 1" mesh="right_ankle_link" />
                            </body>
                        </body>
                    <!-- </body>
                </body> -->
            </body>
            <body name="torso_link" pos="-7.2038e-05 -1.27022e-05 0.0737992">
                <inertial pos="0.000858839 0.0021204 -0.124657" quat="0.994053 -0.0162551 0.0036669 0.107618" mass="17.8896" diaginertia="0.0903162 0.0887643 0.00291432" />
                <joint name="torso_joint" pos="0 0 0" axis="0 0 1" limited="true" range="-0.05 0.05" />
                <geom type="mesh" contype="0" conaffinity="0" group="1" rgba="0.870588 0.909804 1 1" mesh="torso_link" />
                <geom type="mesh" rgba="0.870588 0.909804 1 1" mesh="torso_link" />
                <geom pos="0.013358 -3.0825e-05 0.1797" type="mesh" contype="0" conaffinity="0" group="1" rgba="0.792157 0.819608 0.933333 1" mesh="head_yaw_Link" />
                <geom pos="0.013358 -3.0825e-05 0.1797" type="mesh" rgba="0.792157 0.819608 0.933333 1" mesh="head_yaw_Link" />
                <geom pos="0.0178846 -0.0274648 0.2332" type="mesh" contype="0" conaffinity="0" group="1" rgba="0.792157 0.819608 0.933333 1" mesh="head_pitch_Link" />
                <geom pos="0.0178846 -0.0274648 0.2332" type="mesh" rgba="0.792157 0.819608 0.933333 1" mesh="head_pitch_Link" />
                <geom pos="0.034226 0.0060351 0.1081" type="mesh" contype="0" conaffinity="0" group="1" rgba="0.792157 0.819608 0.933333 1" mesh="imu_Link" />
                <geom pos="0.034226 0.0060351 0.1081" type="mesh" rgba="0.792157 0.819608 0.933333 1" mesh="imu_Link" />
                <body name="left_shoulder_pitch_link" pos="-0.013735 0.16715 0.1722">
                    <inertial pos="-0.00285587 0.0161971 -0.00454433" quat="0.212392 0.627327 0.32629 0.674452" mass="0.0255167" diaginertia="1.9664e-05 1.59983e-05 7.91489e-06" />
                    <!-- <joint name="left_shoulder_pitch_joint" pos="0 0 0" axis="0.17365 -0.984808 0" limited="true" range="-2.87 2.87" /> -->
                    <joint name="left_shoulder_pitch_joint_x" pos="0 0 0" axis="0.17365 0 0" range="-2.87 2.87" />
                    <joint name="left_shoulder_pitch_joint_y" pos="0 0 0" axis="0 -0.984808 0" range="-2.87 2.87" />
                    <joint name="left_shoulder_pitch_joint_z" pos="0 0 0" axis="0 0 0" range="-2.87 2.87" />
                    <geom type="mesh" contype="0" conaffinity="0" group="1" rgba="0.101961 0.101961 0.101961 1" mesh="left_shoulder_pitch_link" />
                    <geom type="mesh" rgba="0.101961 0.101961 0.101961 1" mesh="left_shoulder_pitch_link" />
                    <!-- <body name="left_shoulder_roll_link" pos="0.023704 0.037181 -0.019689">
                        <inertial pos="-0.0284808 -0.00502193 -0.0544067" quat="0.642497 0.0193198 0.0230245 0.765698" mass="0.0301968" diaginertia="4.37441e-05 3.99083e-05 3.88107e-06" />
                        <joint name="left_shoulder_roll_joint" pos="0 0 0" axis="0.984808 0.17365 0" limited="true" range="-0.34 3.11" />
                        <geom type="mesh" contype="0" conaffinity="0" group="1" rgba="0.792157 0.819608 0.933333 1" mesh="left_shoulder_roll_link" />
                        <geom type="mesh" rgba="0.792157 0.819608 0.933333 1" mesh="left_shoulder_roll_link" />
                        <body name="left_shoulder_yaw_link" pos="-0.0113745 -0.00200564 -0.11875">
                            <inertial pos="2.81361e-06 -1.59568e-05 -0.0194961" quat="0.642788 -0.000381216 0.000319878 0.766044" mass="0.0188273" diaginertia="1.07696e-05 7.98266e-06 7.85666e-06" />
                            <joint name="left_shoulder_yaw_joint" pos="0 0 0" axis="0 0 1" limited="true" range="-1.3 4.45" />
                            <geom type="mesh" contype="0" conaffinity="0" group="1" rgba="0.792157 0.819608 0.933333 1" mesh="left_shoulder_yaw_link" />
                            <geom type="mesh" rgba="0.792157 0.819608 0.933333 1" mesh="right_shoulder_yaw_link" /> -->
                            <body name="left_elbow_link" pos="0.0048274 -0.027378 -0.051">
                                <inertial pos="0.102474 0.0483266 -3.11959e-08" quat="-0.0616339 0.704416 0.0616339 0.704416" mass="0.388611" diaginertia="0.00149483 0.00141023 0.000160046" />
                                <joint name="left_elbow_joint" pos="0 0 0" axis="0.17365 -0.984808 0" range="-0.21 2.25" />
                                <geom type="mesh" contype="0" conaffinity="0" group="1" rgba="0.101961 0.101961 0.101961 1" mesh="left_elbow_link" />
                                <geom type="mesh" rgba="0.101961 0.101961 0.101961 1" mesh="left_elbow_link" />
                                <body name="left_hand_link" pos="0.21 0 0">
                                <inertial pos="0.0001 0.0001 -0.0001" quat="0.707107 0 0 0.707107" mass="0.1"
                                    diaginertia="0.0001 0.0001 0.0001" />
                                <joint name="left_hand_joint" pos="0 0 0" axis="0 0 1" range="-1.1 1.1" />
                                <geom type="box" size=".01 .01 .02" rgba="1 0 0 1"  />
                                </body>
                            </body>
                        <!-- </body> -->
                    <!-- </body> -->
                </body>
                <body name="right_shoulder_pitch_link" pos="0.050419 -0.16069 0.1722">
                    <inertial pos="0.00285587 -0.0161971 -0.00454433" quat="-0.32629 0.674452 -0.212392 0.627327" mass="0.0255167" diaginertia="1.9664e-05 1.59983e-05 7.91489e-06" />
                    <!-- <joint name="right_shoulder_pitch_joint" pos="0 0 0" axis="-0.17365 0.984808 0" limited="true" range="-2.87 2.87" /> -->
                    <joint name="right_shoulder_pitch_joint_x" pos="0 0 0" axis="-0.17365 0 0" range="-2.87 2.87" />
                    <joint name="right_shoulder_pitch_joint_y" pos="0 0 0" axis="0 0.984808 0" range="-2.87 2.87" />
                    <joint name="right_shoulder_pitch_joint_z" pos="0 0 0" axis="0 0 0" range="-2.87 2.87" />
                    <geom type="mesh" contype="0" conaffinity="0" group="1" rgba="0.101961 0.101961 0.101961 1" mesh="right_shoulder_pitch_link" />
                    <geom type="mesh" rgba="0.101961 0.101961 0.101961 1" mesh="right_shoulder_pitch_link" />
                    <!-- <body name="right_shoulder_roll_link" pos="-0.023704 -0.037181 -0.019689">
                        <inertial pos="0.0302137 0.0053275 -0.0544067" quat="0.642497 0.0193198 0.0230245 0.765698" mass="0.0301968" diaginertia="4.37441e-05 3.99083e-05 3.88107e-06" />
                        <joint name="right_shoulder_roll_joint" pos="0 0 0" axis="-0.984808 -0.17365 0" limited="true" range="-0.34 3.11" />
                        <geom type="mesh" contype="0" conaffinity="0" group="1" rgba="0.792157 0.819608 0.933333 1" mesh="right_shoulder_roll_link" />
                        <geom type="mesh" rgba="0.792157 0.819608 0.933333 1" mesh="right_shoulder_roll_link" /> -->
                        <!-- <body name="right_shoulder_yaw_link" pos="0.04732 0.0083438 -0.11875">
                            <inertial pos="-2.81361e-06 1.59568e-05 -0.0194961" quat="0.642788 0.000381216 -0.000319878 0.766044" mass="0.0188273" diaginertia="1.07696e-05 7.98266e-06 7.85666e-06" />
                            <joint name="right_shoulder_yaw_joint" pos="0 0 0" axis="0 0 1" limited="true" range="-1.3 4.45" />
                            <geom type="mesh" contype="0" conaffinity="0" group="1" rgba="0.792157 0.819608 0.933333 1" mesh="right_shoulder_yaw_link" />
                            <geom type="mesh" rgba="0.792157 0.819608 0.933333 1" mesh="right_shoulder_yaw_link" /> -->
                            <body name="right_elbow_link" pos="0.0046017 -0.026097 -0.051">
                                <inertial pos="0.103394 0.0431112 3.11959e-08" quat="-0.0616229 0.704417 0.0616229 0.704417" mass="0.388611" diaginertia="0.00149483 0.00141023 0.000160046" />
                                <joint name="right_elbow_joint" pos="0 0 0" axis="-0.17365 0.984808 0" limited="true" range="-1.25 2.61" />
                                <geom type="mesh" contype="0" conaffinity="0" group="1" rgba="0.101961 0.101961 0.101961 1" mesh="right_elbow_link" />
                                <geom type="mesh" rgba="0.101961 0.101961 0.101961 1" mesh="right_elbow_link" />
                                <body name="right_hand_link" pos="0.21 0 0">
                                <inertial pos="0.0001 0.0001 -0.0001" quat="0.707107 0 0 0.707107" mass="0.1"
                                    diaginertia="0.0001 0.0001 0.0001" />
                                <joint name="right_hand_joint" pos="0 0 0" axis="0 0 1" range="-1.1 1.1" />
                                <geom type="box" size=".01 .01 .02" rgba="1 0 0 1"  />
                                </body>
                            </body>
                        <!-- </body> -->
                    <!-- </body> -->
                </body>
            </body>
        </body>
    </worldbody>
    <actuator>
        <position name="left_hip_yaw_joint" joint="left_hip_yaw_joint" />
        <position name="left_hip_roll_joint" joint="left_hip_roll_joint" />
        <position name="left_hip_pitch_joint" joint="left_hip_pitch_joint" />
        <position name="left_knee_joint" joint="left_knee_joint" />
        <position name="left_ankle_joint" joint="left_ankle_joint" />
        <position name="right_hip_yaw_joint" joint="right_hip_yaw_joint" />
        <position name="right_hip_roll_joint" joint="right_hip_roll_joint" />
        <position name="right_hip_pitch_joint" joint="right_hip_pitch_joint" />
        <position name="right_knee_joint" joint="right_knee_joint" />
        <position name="right_ankle_joint" joint="right_ankle_joint" />
        <position name="torso_joint" joint="torso_joint" />
        <position name="left_shoulder_pitch_joint" joint="left_shoulder_pitch_joint" />
        <position name="left_shoulder_roll_joint" joint="left_shoulder_roll_joint" />
        <position name="left_shoulder_yaw_joint" joint="left_shoulder_yaw_joint" />
        <position name="left_elbow_joint" joint="left_elbow_joint" />
        <position name="right_shoulder_pitch_joint" joint="right_shoulder_pitch_joint" />
        <position name="right_shoulder_roll_joint" joint="right_shoulder_roll_joint" />
        <position name="right_shoulder_yaw_joint" joint="right_shoulder_yaw_joint" />
        <position name="right_elbow_joint" joint="right_elbow_joint" />
    </actuator>
</mujoco>
